Workbook

Sheet Read me
A1: Kwetu Farm: animals and their records
A2: Rebuilt from the farm's own records, one row per animal. Records cover cattle from 1/1/2025 and goats and sheep from 31/5/2025, up to September 2026.
A4: How to read the colours
A5: Blue cells | B5: Straight from the farm's records
A6: Orange cells | B6: Filled in by us (an estimate or a choice); check or replace when you know better
A8: What is real and what was filled in
A9: Real: every birth, death, sale, transfer and treatment, with its date, sex and group, comes from the records. So do the farm's tag numbers (e.g. C004, G118) and the prices and weights where they were written down.
A10: Filled in: the records count animals rather than naming them. When the book says '1 She cow died', we chose which cow. Unless the animal has a farm number, the choice of animal is ours.
A11: Filled in: birth dates of animals already on the farm when the records start, breeds, mothers, and prices that weren't written down. Each of these is shaded orange.
A12: Tag numbers: C, G and S plus the farm's own number where the records give one (C004 = cow No 004). Numbers from 201 upwards (C201, G201...) were given by us to animals the records never number.
A14: Sources (all on Google Drive)
A15: Kwetu Livestock Tracker.xlsx: the daily head counts and notes (2025 - 2026 Cow, Goat and Sheep Tracker sheets); 2025 Cow Sales Weight sheet.
A16: Kwetu_Livestock_Medicine_Log: the medicine cards, which name the tag numbers of treated animals.
A17: Kwetu_Daily_Activity_Tracker: Livestock Status notes, Inputs Applied and Sales, July - September 2026.
A18: Photos Data1 - Data9 and the WhatsApp image (head-count books, 2020 - 2021): read on the 'Notebook 2020-21' tab.
A20: Herd on 30/09/2026 (worked out from the Animals tab)
A21: Species | B21: Male | C21: Female | D21: Total
A22: Cattle | B22: =COUNTIFS(Animals!$B:$B,$A22,Animals!$C:$C,"Male",Animals!$J:$J,"On farm") -> 38 | C22: =COUNTIFS(Animals!$B:$B,$A22,Animals!$C:$C,"Female",Animals!$J:$J,"On farm") -> 70 | D22: =B22+C22 -> 108
A23: Goat | B23: =COUNTIFS(Animals!$B:$B,$A23,Animals!$C:$C,"Male",Animals!$J:$J,"On farm") -> 26 | C23: =COUNTIFS(Animals!$B:$B,$A23,Animals!$C:$C,"Female",Animals!$J:$J,"On farm") -> 65 | D23: =B23+C23 -> 91
A24: Sheep | B24: =COUNTIFS(Animals!$B:$B,$A24,Animals!$C:$C,"Male",Animals!$J:$J,"On farm") -> 41 | C24: =COUNTIFS(Animals!$B:$B,$A24,Animals!$C:$C,"Female",Animals!$J:$J,"On farm") -> 102 | D24: =B24+C24 -> 143
A25: Total | B25: =SUM(B22:B24) -> 105 | C25: =SUM(C22:C24) -> 237 | D25: =SUM(D22:D24) -> 342
A27: Tracker on its last day: cattle 108 (14/9/2026), goats 91 (31/8/2026), sheep 143 (17/9/2026). The 'Head-count check' tab compares every month.

Sheet Animals
A1: Tag | B1: Species | C1: Sex | D1: Breed | E1: Date of birth | F1: Age (years) on 30/9/2026 or when it left | G1: Name | H1: Joined the records | I1: How it joined | J1: Status | K1: Left on | L1: Mother (tag) | M1: Farm's own number? | N1: Notes
A2: C002 | B2: Cattle | C2: Female | D2: Boran | E2: 43854 | F2: =ROUND((IF(K2="",DATE(2026,9,30),K2)-E2)/365.25,1) -> 6.3 | H2: 45658 | I2: On the farm when the records start (01/01/2025) | J2: Died | K2: 46137 | M2: Yes
A3: C004 | B3: Cattle | C3: Female | D3: Boran x Sahiwal | E3: 44158 | F3: =ROUND((IF(K3="",DATE(2026,9,30),K3)-E3)/365.25,1) -> 5.4 | H3: 45658 | I3: On the farm when the records start (01/01/2025) | J3: Died | K3: 46139 | M3: Yes
A4: C012 | B4: Cattle | C4: Female | D4: Boran | E4: 45488 | F4: =ROUND((IF(K4="",DATE(2026,9,30),K4)-E4)/365.25,1) -> 2.2 | H4: 45658 | I4: On the farm when the records start (01/01/2025) | J4: On farm | M4: Yes
A5: C017 | B5: Cattle | C5: Male | D5: Boran | E5: 45729 | F5: =ROUND((IF(K5="",DATE(2026,9,30),K5)-E5)/365.25,1) -> 1.5 | H5: 45729 | I5: Born on the farm | J5: On farm | L5: C261 | M5: Yes
A6: C025 | B6: Cattle | C6: Female | D6: Boran | E6: 45519 | F6: =ROUND((IF(K6="",DATE(2026,9,30),K6)-E6)/365.25,1) -> 2.1 | H6: 45658 | I6: On the farm when the records start (01/01/2025) | J6: On farm | M6: Yes
A7: C045 | B7: Cattle | C7: Female | D7: Sahiwal | E7: 44379 | F7: =ROUND((IF(K7="",DATE(2026,9,30),K7)-E7)/365.25,1) -> 5.2 | H7: 45658 | I7: On the farm when the records start (01/01/2025) | J7: On farm | M7: Yes
A8: C055 | B8: Cattle | C8: Male | D8: Boran | E8: 45362 | F8: =ROUND((IF(K8="",DATE(2026,9,30),K8)-E8)/365.25,1) -> 2 | H8: 45658 | I8: On the farm when the records start (01/01/2025) | J8: Sold | K8: 46099 | M8: Yes
A9: C072 | B9: Cattle | C9: Female | D9: Boran | E9: 43820 | F9: =ROUND((IF(K9="",DATE(2026,9,30),K9)-E9)/365.25,1) -> 6.8 | H9: 45658 | I9: On the farm when the records start (01/01/2025) | J9: On farm | M9: Yes
A10: C103 | B10: Cattle | C10: Male | D10: Boran x Sahiwal | E10: 43446 | F10: =ROUND((IF(K10="",DATE(2026,9,30),K10)-E10)/365.25,1) -> 7.3 | H10: 45658 | I10: On the farm when the records start (01/01/2025) | J10: Sold | K10: 46113 | M10: Yes | N10: Sex corrected in the count on 13/02/2026
A11: C105 | B11: Cattle | C11: Female | D11: Boran | E11: 45968 | F11: =ROUND((IF(K11="",DATE(2026,9,30),K11)-E11)/365.25,1) -> 0.9 | H11: 45968 | I11: Born on the farm | J11: On farm | L11: C283 | M11: Yes
A12: C106 | B12: Cattle | C12: Male | D12: Boran | E12: 45424 | F12: =ROUND((IF(K12="",DATE(2026,9,30),K12)-E12)/365.25,1) -> 1.9 | H12: 45658 | I12: On the farm when the records start (01/01/2025) | J12: Sold | K12: 46112 | M12: Yes
A13: C108 | B13: Cattle | C13: Male | D13: Sahiwal | E13: 45473 | F13: =ROUND((IF(K13="",DATE(2026,9,30),K13)-E13)/365.25,1) -> 2.3 | H13: 45658 | I13: On the farm when the records start (01/01/2025) | J13: On farm | M13: Yes
A14: C111 | B14: Cattle | C14: Female | D14: Boran | E14: 44399 | F14: =ROUND((IF(K14="",DATE(2026,9,30),K14)-E14)/365.25,1) -> 5.2 | H14: 45658 | I14: On the farm when the records start (01/01/2025) | J14: On farm | M14: Yes
A15: C116 | B15: Cattle | C15: Male | D15: Sahiwal | E15: 46019 | F15: =ROUND((IF(K15="",DATE(2026,9,30),K15)-E15)/365.25,1) -> 0.8 | H15: 46019 | I15: Born on the farm | J15: On farm | L15: C276 | M15: Yes
A16: C121 | B16: Cattle | C16: Male | D16: Boran x Sahiwal | E16: 44687 | F16: =ROUND((IF(K16="",DATE(2026,9,30),K16)-E16)/365.25,1) -> 3.9 | H16: 45658 | I16: On the farm when the records start (01/01/2025) | J16: Sold | K16: 46111 | M16: Yes
A17: C136 | B17: Cattle | C17: Male | D17: Boran | E17: 45976 | F17: =ROUND((IF(K17="",DATE(2026,9,30),K17)-E17)/365.25,1) -> 0.4 | H17: 45976 | I17: Born on the farm | J17: Died | K17: 46137 | L17: C265 | M17: Yes
A18: C201 | B18: Cattle | C18: Male | D18: Boran x Sahiwal | E18: 44463 | F18: =ROUND((IF(K18="",DATE(2026,9,30),K18)-E18)/365.25,1) -> 4.2 | H18: 45658 | I18: On the farm when the records start (01/01/2025) | J18: Died | K18: 45986 | M18: No
A19: C202 | B19: Cattle | C19: Male | D19: Boran x Sahiwal | E19: 42489 | F19: =ROUND((IF(K19="",DATE(2026,9,30),K19)-E19)/365.25,1) -> 9.2 | H19: 45658 | I19: On the farm when the records start (01/01/2025) | J19: Sold | K19: 45838 | M19: No
A20: C203 | B20: Cattle | C20: Male | D20: Boran | E20: 42706 | F20: =ROUND((IF(K20="",DATE(2026,9,30),K20)-E20)/365.25,1) -> 8.9 | H20: 45658 | I20: On the farm when the records start (01/01/2025) | J20: Sold | K20: 45947 | M20: No
A21: C204 | B21: Cattle | C21: Male | D21: Boran x Sahiwal | E21: 42648 | F21: =ROUND((IF(K21="",DATE(2026,9,30),K21)-E21)/365.25,1) -> 9 | H21: 45658 | I21: On the farm when the records start (01/01/2025) | J21: Sold | K21: 45945 | M21: No
A22: C205 | B22: Cattle | C22: Male | D22: Sahiwal | E22: 43272 | F22: =ROUND((IF(K22="",DATE(2026,9,30),K22)-E22)/365.25,1) -> 7.3 | H22: 45658 | I22: On the farm when the records start (01/01/2025) | J22: Sold | K22: 45944 | M22: No
A23: C206 | B23: Cattle | C23: Male | D23: Boran x Sahiwal | E23: 42887 | F23: =ROUND((IF(K23="",DATE(2026,9,30),K23)-E23)/365.25,1) -> 7.6 | H23: 45658 | I23: On the farm when the records start (01/01/2025) | J23: Died | K23: 45665 | M23: No
A24: C207 | B24: Cattle | C24: Male | D24: Sahiwal | E24: 42747 | F24: =ROUND((IF(K24="",DATE(2026,9,30),K24)-E24)/365.25,1) -> 8.5 | H24: 45658 | I24: On the farm when the records start (01/01/2025) | J24: Sold | K24: 45838 | M24: No
A25: C208 | B25: Cattle | C25: Male | D25: Boran x Sahiwal | E25: 42964 | F25: =ROUND((IF(K25="",DATE(2026,9,30),K25)-E25)/365.25,1) -> 7.9 | H25: 45658 | I25: On the farm when the records start (01/01/2025) | J25: Sold | K25: 45838 | M25: No
A26: C209 | B26: Cattle | C26: Male | D26: Boran | E26: 43700 | F26: =ROUND((IF(K26="",DATE(2026,9,30),K26)-E26)/365.25,1) -> 5.9 | H26: 45658 | I26: On the farm when the records start (01/01/2025) | J26: Sold | K26: 45838 | M26: No
A27: C210 | B27: Cattle | C27: Male | D27: Boran | E27: 43289 | F27: =ROUND((IF(K27="",DATE(2026,9,30),K27)-E27)/365.25,1) -> 6.7 | H27: 45658 | I27: On the farm when the records start (01/01/2025) | J27: Sold | K27: 45728 | M27: No
A28: C211 | B28: Cattle | C28: Male | D28: Boran | E28: 44065 | F28: =ROUND((IF(K28="",DATE(2026,9,30),K28)-E28)/365.25,1) -> 5.6 | H28: 45658 | I28: On the farm when the records start (01/01/2025) | J28: Given away / eaten | K28: 46106 | M28: No
A29: C212 | B29: Cattle | C29: Male | D29: Boran x Sahiwal | E29: 43679 | F29: =ROUND((IF(K29="",DATE(2026,9,30),K29)-E29)/365.25,1) -> 5.9 | H29: 45658 | I29: On the farm when the records start (01/01/2025) | J29: Sold | K29: 45838 | M29: No
... A31: C214 | B31: Cattle | C31: Male | D31: Sahiwal | E31: 44247 | F31: =ROUND((IF(K31="",DATE(2026,9,30),K31)-E31)/365.25,1) -> 4.7 | H31: 45658 | I31: On the farm when the records start (01/01/2025) | J31: Sold | K31: 45954 | M31: No
A32: C215 | B32: Cattle | C32: Male | D32: Sahiwal | E32: 43921 | F32: =ROUND((IF(K32="",DATE(2026,9,30),K32)-E32)/365.25,1) -> 6.5 | H32: 45658 | I32: On the farm when the records start (01/01/2025) | J32: On farm | M32: No
A33: C216 | B33: Cattle | C33: Male | D33: Boran x Sahiwal | E33: 42836 | F33: =ROUND((IF(K33="",DATE(2026,9,30),K33)-E33)/365.25,1) -> 8.2 | H33: 45658 | I33: On the farm when the records start (01/01/2025) | J33: Sold | K33: 45838 | M33: No
A34: C217 | B34: Cattle | C34: Male | D34: Boran | E34: 43528 | F34: =ROUND((IF(K34="",DATE(2026,9,30),K34)-E34)/365.25,1) -> 6.2 | H34: 45658 | I34: On the farm when the records start (01/01/2025) | J34: Died | K34: 45805 | M34: No
A35: C218 | B35: Cattle | C35: Male | D35: Boran | E35: 43030 | F35: =ROUND((IF(K35="",DATE(2026,9,30),K35)-E35)/365.25,1) -> 7.7 | H35: 45658 | I35: On the farm when the records start (01/01/2025) | J35: Sold | K35: 45838 | M35: No
A36: C219 | B36: Cattle | C36: Male | D36: Sahiwal | E36: 43423 | F36: =ROUND((IF(K36="",DATE(2026,9,30),K36)-E36)/365.25,1) -> 6.9 | H36: 45658 | I36: On the farm when the records start (01/01/2025) | J36: Sold | K36: 45945 | M36: No
A37: C220 | B37: Cattle | C37: Male | D37: Boran | E37: 44064 | F37: =ROUND((IF(K37="",DATE(2026,9,30),K37)-E37)/365.25,1) -> 5.2 | H37: 45658 | I37: On the farm when the records start (01/01/2025) | J37: Sold | K37: 45954 | M37: No
A38: C221 | B38: Cattle | C38: Male | D38: Boran x Sahiwal | E38: 42667 | F38: =ROUND((IF(K38="",DATE(2026,9,30),K38)-E38)/365.25,1) -> 9.9 | H38: 45658 | I38: On the farm when the records start (01/01/2025) | J38: On farm | M38: No
A39: C222 | B39: Cattle | C39: Male | D39: Sahiwal | E39: 43046 | F39: =ROUND((IF(K39="",DATE(2026,9,30),K39)-E39)/365.25,1) -> 7.6 | H39: 45658 | I39: On the farm when the records start (01/01/2025) | J39: Sold | K39: 45838 | M39: No
A40: C223 | B40: Cattle | C40: Male | D40: Sahiwal | E40: 43871 | F40: =ROUND((IF(K40="",DATE(2026,9,30),K40)-E40)/365.25,1) -> 5.7 | H40: 45658 | I40: On the farm when the records start (01/01/2025) | J40: Sold | K40: 45955 | M40: No
A41: C224 | B41: Cattle | C41: Male | D41: Sahiwal | E41: 43744 | F41: =ROUND((IF(K41="",DATE(2026,9,30),K41)-E41)/365.25,1) -> 6 | H41: 45658 | I41: On the farm when the records start (01/01/2025) | J41: Sold | K41: 45947 | M41: No
...

Sheet Births
A1: Date | B1: Species | C1: Mother (tag) | D1: Young (tags) | E1: Sex of young | F1: Single or twins | G1: Source
A2: 45659 | B2: Cattle | C2: C254 | D2: C322 | E2: Male | F2: Single | G2: Livestock Tracker, 2025 - 2026 Cow Tracker, 02/01/2025
A3: 45661 | B3: Cattle | C3: C244 | D3: C323 | E3: Female | F3: Single | G3: Livestock Tracker, 2025 - 2026 Cow Tracker, 04/01/2025
A4: 45663 | B4: Cattle | C4: C246 | D4: C324 | E4: Male | F4: Single | G4: Livestock Tracker, 2025 - 2026 Cow Tracker, 06/01/2025
A5: 45667 | B5: Cattle | C5: C275 | D5: C325 | E5: Male | F5: Single | G5: Livestock Tracker, 2025 - 2026 Cow Tracker, 10/01/2025: "1 He Calf new born"
A6: 45672 | B6: Cattle | C6: C247 | D6: C326 | E6: Male | F6: Single | G6: Livestock Tracker, 2025 - 2026 Cow Tracker, 15/01/2025
A7: 45679 | B7: Cattle | C7: C251 | D7: C327 | E7: Female | F7: Single | G7: Livestock Tracker, 2025 - 2026 Cow Tracker, 22/01/2025
A8: 45729 | B8: Cattle | C8: C261 | D8: C017 | E8: Male | F8: Single | G8: Livestock Tracker, 2025 - 2026 Cow Tracker, 13/03/2025: "1 He Calf new born"
A9: 45761 | B9: Cattle | C9: C266 | D9: C328 | E9: Male | F9: Single | G9: Livestock Tracker, 2025 - 2026 Cow Tracker, 14/04/2025
A10: 45772 | B10: Cattle | C10: C111 | D10: C329 | E10: Male | F10: Single | G10: Livestock Tracker, 2025 - 2026 Cow Tracker, 25/04/2025
A11: 45807 | B11: Cattle | C11: C279 | D11: C330 | E11: Male | F11: Single | G11: Livestock Tracker, 2025 - 2026 Cow Tracker, 30/05/2025: "1 She cow new born"
A12: 45820 | B12: Cattle | C12: C239 | D12: C332 | E12: Female | F12: Single | G12: Livestock Tracker, 2025 - 2026 Cow Tracker, 12/06/2025: "1 She calve new born"
A13: 45820 | B13: Goat | C13: G254 | D13: G305 | E13: Male | F13: Single | G13: Livestock Tracker, 2025 - 2026 Goat Tracker, 12/06/2025: "1 He goat new born"
... A151: 46277 | B151: Cattle | C151: C267 | D151: C366 | E151: Male | F151: Single | G151: Livestock Tracker, 2025 - 2026 Cow Tracker, 12/09/2026: "1 He new born"

Sheet Deaths
A1: Date | B1: Tag | C1: Species | D1: Sex | E1: Age at death (whole years) | F1: Cause of death | G1: What the record says | H1: Source
A2: 45665 | B2: C206 | C2: Cattle | D2: Male | E2: 7 | F2: Not recorded | G2: 1 he died | H2: Livestock Tracker, 2025 - 2026 Cow Tracker, 08/01/2025: "1 he died"
A3: 45710 | B3: C247 | C3: Cattle | D3: Female | E3: 5 | F3: Injured by bulls | G3: 1 she died (injured by bull) | H3: Livestock Tracker, 2025 - 2026 Cow Tracker, 22/02/2025: "1 She died (injured by bull)"
A4: 45757 | B4: C213 | C4: Cattle | D4: Male | E4: 5 | F4: Injured by bulls | G4: 1 he cow died (injured by bulls) | H4: Livestock Tracker, 2025 - 2026 Cow Tracker, 10/04/2025: "1 He cow died (Injured by bulls)"
A5: 45794 | B5: C232 | C5: Cattle | D5: Male | E5: 6 | F5: Not recorded | G5: 1 he cow died | H5: Livestock Tracker, 2025 - 2026 Cow Tracker, 17/05/2025: "1 He cow died"
A6: 45796 | B6: C226 | C6: Cattle | D6: Male | E6: 6 | F6: Not recorded | G6: 1 he cow died | H6: Livestock Tracker, 2025 - 2026 Cow Tracker, 19/05/2025: "1 He cow died"
A7: 45805 | B7: C217 | C7: Cattle | D7: Male | E7: 6 | F7: Not recorded | G7: 1 he cow died | H7: Livestock Tracker, 2025 - 2026 Cow Tracker, 28/05/2025: "1 He cow died"
A8: 45810 | B8: C270 | C8: Cattle | D8: Female | E8: 3 | F8: Not recorded | G8: 1 she cow died | H8: Livestock Tracker, 2025 - 2026 Cow Tracker, 02/06/2025: "1 she cow died"
A9: 45811 | B9: G295 | C9: Goat | D9: Female | E9: 1 | F9: Not recorded | G9: 1 she goat died | H9: Livestock Tracker, 2025 - 2026 Goat Tracker, 03/06/2025: "1 She goat died"
A10: 45821 | B10: S296 | C10: Sheep | D10: Female | E10: 4 | F10: Not recorded | G10: 1 she died | H10: Livestock Tracker, 2025-2026 Sheep Tracker, 13/06/2025: "1 She died"
A11: 45829 | B11: S220 | C11: Sheep | D11: Male | E11: 5 | F11: Not recorded | G11: 1 he sheep died | H11: Livestock Tracker, 2025-2026 Sheep Tracker, 21/06/2025: "1 He sheep died"
A12: 45830 | B12: C278 | C12: Cattle | D12: Female | E12: 8 | F12: Not recorded | G12: 1 she cow died | H12: Livestock Tracker, 2025 - 2026 Cow Tracker, 22/06/2025: "1 She cow died"
A13: 45830 | B13: G307 | C13: Goat | D13: Male | E13: 0 | F13: Not recorded | G13: 1 he died | H13: Livestock Tracker, 2025 - 2026 Goat Tracker, 22/06/2025: "1 He died"
... A110: 46281 | B110: S425 | C110: Sheep | D110: Female | E110: 0 | F110: Not recorded | G110: 1 she kid died | H110: Livestock Tracker, 2025-2026 Sheep Tracker, 16/09/2026: "1 she kid died"

Sheet Sales & exits
A1: Date | B1: Tag | C1: Species | D1: Sex | E1: What happened | F1: Amount (KES) | G1: Buyer / note | H1: Weight (kg) | I1: Where the price comes from | J1: What the record says | K1: Source
A2: 45728 | B2: C210 | C2: Cattle | D2: Male | E2: Sold | F2: 100000 | G2: Not recorded | I2: Estimate: average Farmers Choice price for bulls in 2025 | J2: i bull sold | K2: Livestock Tracker, 2025 - 2026 Cow Tracker, 12/03/2025: "I bull sold"
A3: 45819 | B3: S208 | C3: Sheep | D3: Male | E3: Sold | F3: 10500 | G3: Not recorded | I3: Estimate: about 30 kg at KES 350/kg | J3: 2 she sold | K3: Livestock Tracker, 2025-2026 Sheep Tracker, 11/06/2025: "2 He and 2 She sold"
A4: 45819 | B4: S222 | C4: Sheep | D4: Male | E4: Sold | F4: 10500 | G4: Not recorded | I4: Estimate: about 30 kg at KES 350/kg | J4: 2 she sold | K4: Livestock Tracker, 2025-2026 Sheep Tracker, 11/06/2025: "2 He and 2 She sold"
A5: 45819 | B5: S306 | C5: Sheep | D5: Female | E5: Sold | F5: 9800 | G5: Not recorded | I5: Estimate: about 28 kg at KES 350/kg | J5: 2 she sold | K5: Livestock Tracker, 2025-2026 Sheep Tracker, 11/06/2025: "2 He and 2 She sold"
A6: 45819 | B6: S293 | C6: Sheep | D6: Female | E6: Sold | F6: 9800 | G6: Not recorded | I6: Estimate: about 28 kg at KES 350/kg | J6: 2 she sold | K6: Livestock Tracker, 2025-2026 Sheep Tracker, 11/06/2025: "2 He and 2 She sold"
A7: 45838 | B7: C331 | C7: Cattle | D7: Male | E7: Sold | F7: 86088 | G7: Farmers Choice | H7: 360 | I7: 2025 Cow Sales Weight sheet | J7: 10 bulls sold | K7: Livestock Tracker, 2025 - 2026 Cow Tracker, 30/06/2025: "10 Bulls Sold"
A8: 45838 | B8: C208 | C8: Cattle | D8: Male | E8: Sold | F8: 97545 | G8: Farmers Choice | H8: 392 | I8: 2025 Cow Sales Weight sheet | J8: 10 bulls sold | K8: Livestock Tracker, 2025 - 2026 Cow Tracker, 30/06/2025: "10 Bulls Sold"
A9: 45838 | B9: C233 | C9: Cattle | D9: Male | E9: Sold | F9: 76843 | G9: Farmers Choice | H9: 360 | I9: 2025 Cow Sales Weight sheet | J9: 10 bulls sold | K9: Livestock Tracker, 2025 - 2026 Cow Tracker, 30/06/2025: "10 Bulls Sold"
A10: 45838 | B10: C222 | C10: Cattle | D10: Male | E10: Sold | F10: 121680 | G10: Farmers Choice | H10: 459 | I10: 2025 Cow Sales Weight sheet | J10: 10 bulls sold | K10: Livestock Tracker, 2025 - 2026 Cow Tracker, 30/06/2025: "10 Bulls Sold"
A11: 45838 | B11: C207 | C11: Cattle | D11: Male | E11: Sold | F11: 92492 | G11: Farmers Choice | H11: 372 | I11: 2025 Cow Sales Weight sheet | J11: 10 bulls sold | K11: Livestock Tracker, 2025 - 2026 Cow Tracker, 30/06/2025: "10 Bulls Sold"
A12: 45838 | B12: C218 | C12: Cattle | D12: Male | E12: Sold | F12: 117145 | G12: Farmers Choice | H12: 427 | I12: 2025 Cow Sales Weight sheet | J12: 10 bulls sold | K12: Livestock Tracker, 2025 - 2026 Cow Tracker, 30/06/2025: "10 Bulls Sold"
A13: 45838 | B13: C216 | C13: Cattle | D13: Male | E13: Sold | F13: 101010 | G13: Farmers Choice | H13: 420 | I13: 2025 Cow Sales Weight sheet | J13: 10 bulls sold | K13: Livestock Tracker, 2025 - 2026 Cow Tracker, 30/06/2025: "10 Bulls Sold"
A14: 45838 | B14: C202 | C14: Cattle | D14: Male | E14: Sold | F14: 100382 | G14: Farmers Choice | H14: 420 | I14: 2025 Cow Sales Weight sheet | J14: 10 bulls sold | K14: Livestock Tracker, 2025 - 2026 Cow Tracker, 30/06/2025: "10 Bulls Sold"
A15: 45838 | B15: C209 | C15: Cattle | D15: Male | E15: Sold | F15: 92684 | G15: Farmers Choice | H15: 384 | I15: 2025 Cow Sales Weight sheet | J15: 10 bulls sold | K15: Livestock Tracker, 2025 - 2026 Cow Tracker, 30/06/2025: "10 Bulls Sold"
A16: 45838 | B16: C212 | C16: Cattle | D16: Male | E16: Sold | F16: 119630 | G16: Farmers Choice | H16: 451 | I16: 2025 Cow Sales Weight sheet | J16: 10 bulls sold | K16: Livestock Tracker, 2025 - 2026 Cow Tracker, 30/06/2025: "10 Bulls Sold"
A17: 45881 | B17: C229 | C17: Cattle | D17: Male | E17: Sold | F17: 93000 | G17: Not recorded | H17: 300 | I17: 2025 Cow Sales Weight sheet rows 11-12 (KES 310/kg live) | J17: 2 bulls sold | K17: Livestock Tracker, 2025 - 2026 Cow Tracker, 12/08/2025: "2 Bulls Sold"
A18: 45881 | B18: C230 | C18: Cattle | D18: Male | E18: Sold | F18: 83700 | G18: Not recorded | H18: 270 | I18: 2025 Cow Sales Weight sheet rows 11-12 (KES 310/kg live) | J18: 2 bulls sold | K18: Livestock Tracker, 2025 - 2026 Cow Tracker, 12/08/2025: "2 Bulls Sold"
A19: 45882 | B19: G311 | C19: Goat | D19: Male | E19: Missing (count correction) | J19: Count went down with no explanation | K19: Livestock Tracker, 2025 - 2026 Goat Tracker, 13/08/2025
A20: 45897 | B20: S235 | C20: Sheep | D20: Male | E20: Sold | F20: 10500 | G20: Not recorded | I20: Estimate: about 30 kg at KES 350/kg | J20: 1 he sheep sold | K20: Livestock Tracker, 2025-2026 Sheep Tracker, 28/08/2025: "1 He sheep sold"
A21: 45900 | B21: G321 | C21: Goat | D21: Female | E21: Missing (count correction) | J21: No explanation | K21: Livestock Tracker, 2025 - 2026 Goat Tracker, 31/08/2025: "No explanation"
A22: 45901 | B22: G205 | C22: Goat | D22: Male | E22: Sold | F22: 10500 | G22: Not recorded | I22: Estimate: about 30 kg at KES 350/kg (the farm's 2026 rate) | J22: 1 he goat sold | K22: Livestock Tracker, 2025 - 2026 Goat Tracker, 01/09/2025: "1 He goat sold"
A23: 45905 | B23: G254 | C23: Goat | D23: Female | E23: Missing (count correction) | J23: No explanation | K23: Livestock Tracker, 2025 - 2026 Goat Tracker, 05/09/2025: "No explanation"
A24: 45934 | B24: C268 | C24: Cattle | D24: Female | E24: Sold | F24: 70000 | G24: Not recorded | I24: Estimate: cull cow | J24: 2 she cows sold | K24: Livestock Tracker, 2025 - 2026 Cow Tracker, 04/10/2025: "2 She cows sold"
A25: 45934 | B25: C239 | C25: Cattle | D25: Female | E25: Sold | F25: 70000 | G25: Not recorded | I25: Estimate: cull cow | J25: 2 she cows sold | K25: Livestock Tracker, 2025 - 2026 Cow Tracker, 04/10/2025: "2 She cows sold"
A26: 45941 | B26: C231 | C26: Cattle | D26: Male | E26: Sold | F26: 100000 | G26: Not recorded | I26: Estimate: average Farmers Choice price for bulls in 2025 | J26: 1 he bull sold | K26: Livestock Tracker, 2025 - 2026 Cow Tracker, 11/10/2025: "1 He bull sold"
A27: 45944 | B27: C205 | C27: Cattle | D27: Male | E27: Sold | F27: 100000 | G27: Not recorded | I27: Estimate: average Farmers Choice price for bulls in 2025 | J27: 1 he bull sold | K27: Livestock Tracker, 2025 - 2026 Cow Tracker, 14/10/2025: "1 He bull sold"
A28: 45945 | B28: C204 | C28: Cattle | D28: Male | E28: Sold | F28: 100000 | G28: Not recorded | I28: Estimate: average Farmers Choice price for bulls in 2025 | J28: 2 bulls sold | K28: Livestock Tracker, 2025 - 2026 Cow Tracker, 15/10/2025: "2 Bulls Sold"
A29: 45945 | B29: C219 | C29: Cattle | D29: Male | E29: Sold | F29: 100000 | G29: Not recorded | I29: Estimate: average Farmers Choice price for bulls in 2025 | J29: 2 bulls sold | K29: Livestock Tracker, 2025 - 2026 Cow Tracker, 15/10/2025: "2 Bulls Sold"
A30: 45946 | B30: C228 | C30: Cattle | D30: Male | E30: Sold | F30: 100000 | G30: Not recorded | I30: Estimate: average Farmers Choice price for bulls in 2025 | J30: 1 bul sold | K30: Livestock Tracker, 2025 - 2026 Cow Tracker, 16/10/2025: "1 Bul Sold"
A31: 45947 | B31: C225 | C31: Cattle | D31: Male | E31: Sold | F31: 100000 | G31: Not recorded | I31: Estimate: average Farmers Choice price for bulls in 2025 | J31: 3 bulls sold | K31: Livestock Tracker, 2025 - 2026 Cow Tracker, 17/10/2025: "3 Bulls sold"
A32: 45947 | B32: C224 | C32: Cattle | D32: Male | E32: Sold | F32: 100000 | G32: Not recorded | I32: Estimate: average Farmers Choice price for bulls in 2025 | J32: 3 bulls sold | K32: Livestock Tracker, 2025 - 2026 Cow Tracker, 17/10/2025: "3 Bulls sold"
A33: 45947 | B33: C203 | C33: Cattle | D33: Male | E33: Sold | F33: 100000 | G33: Not recorded | I33: Estimate: average Farmers Choice price for bulls in 2025 | J33: 3 bulls sold | K33: Livestock Tracker, 2025 - 2026 Cow Tracker, 17/10/2025: "3 Bulls sold"
A34: 45954 | B34: C220 | C34: Cattle | D34: Male | E34: Sold | F34: 100000 | G34: Not recorded | I34: Estimate: average Farmers Choice price for bulls in 2025 | J34: 2 bulls sold | K34: Livestock Tracker, 2025 - 2026 Cow Tracker, 24/10/2025: "2 Bulls Sold"
A35: 45954 | B35: C214 | C35: Cattle | D35: Male | E35: Sold | F35: 100000 | G35: Not recorded | I35: Estimate: average Farmers Choice price for bulls in 2025 | J35: 2 bulls sold | K35: Livestock Tracker, 2025 - 2026 Cow Tracker, 24/10/2025: "2 Bulls Sold"
... A38: 45958 | B38: C238 | C38: Cattle | D38: Female | E38: Sold | F38: 70000 | G38: Not recorded | I38: Estimate: cull cow | J38: 2 she cows sold | K38: Livestock Tracker, 2025 - 2026 Cow Tracker, 28/10/2025: "2 She cows sold"
A39: 45958 | B39: G212 | C39: Goat | D39: Male | E39: Given away / eaten | F39: 0 | G39: 1 he goat given to chief | J39: 1 he goat given to chief | K39: Livestock Tracker, 2025 - 2026 Goat Tracker, 28/10/2025: "1 He goat given to chief"
A40: 45960 | B40: C240 | C40: Cattle | D40: Female | E40: Sold | F40: 70000 | G40: Not recorded | I40: Estimate: cull cow | J40: 2 she cows sold (old) | K40: Livestock Tracker, 2025 - 2026 Cow Tracker, 30/10/2025: "2 She cows sold (Old)"
A41: 45960 | B41: C269 | C41: Cattle | D41: Female | E41: Sold | F41: 70000 | G41: Not recorded | I41: Estimate: cull cow | J41: 2 she cows sold (old) | K41: Livestock Tracker, 2025 - 2026 Cow Tracker, 30/10/2025: "2 She cows sold (Old)"
A42: 45961 | B42: C248 | C42: Cattle | D42: Female | E42: Sold | F42: 70000 | G42: Not recorded | I42: Estimate: cull cow | J42: 2 she cows sold | K42: Livestock Tracker, 2025 - 2026 Cow Tracker, 31/10/2025: "1 She calf died, 2 She cows sold"
...

Sheet Health records
A1: Date | B1: Tag | C1: Species | D1: Record type | E1: Illness / problem | F1: Temperature (°C) | G1: Medicine | H1: Dose | I1: Notes | J1: Source
A2: 46106 | B2: C354 | C2: Cattle | D2: TREATMENT | G2: Ivermectin + Oxytetracycline 10% LA | H2: 10 ml + 20 ml | I2: Treated the new bull on arrival | J2: Medicine Log
A3: 46106 | B3: C116 | C3: Cattle | D3: ILLNESS | E3: East Coast Fever (treated with Bupalex) | G3: Bupalex + Oxytetracycline 10% LA | H3: 10 ml + 10 ml | I3: Sick calf | J3: Medicine Log
A4: 46106 | B4: S337 | C4: Sheep | D4: ILLNESS | E4: Sick (not stated) | G4: Oxytetracycline 10% LA | H4: 4 ml | I4: Sheep number unreadable on the card | J4: Medicine Log
A5: 46107 | B5: C045 | C5: Cattle | D5: ILLNESS | E5: Foot and Mouth Disease | G5: Oxytetracycline 10% LA | H5: 20 ml | J5: Medicine Log
A6: 46108 | B6: C045 | C6: Cattle | D6: TREATMENT | E6: Foot and Mouth Disease | G6: Oxytetracycline 10% LA | H6: 20 ml | I6: Repeat treatment | J6: Medicine Log
A7: 46123 | B7: C105 | C7: Cattle | D7: ILLNESS | E7: East Coast Fever | F7: 40 | G7: Bupalex | H7: 20 ml | J7: Medicine Log
A8: 46124 | B8: C105 | C8: Cattle | D8: TREATMENT | E8: East Coast Fever | G8: Bupalex | H8: 20 ml | I8: Repeat treatment | J8: Medicine Log
A9: 46124 | B9: C004 | C9: Cattle | D9: ILLNESS | E9: East Coast Fever | F9: 40 | G9: Bupalex | H9: 20 ml | J9: Medicine Log
A10: 46124 | B10: C108 | C10: Cattle | D10: ILLNESS | E10: East Coast Fever | F10: 40 | G10: Bupalex | H10: 20 ml | J10: Medicine Log
A11: 46127 | B11: C108 | C11: Cattle | D11: TREATMENT | E11: East Coast Fever | G11: Bupalex | H11: 10 ml | I11: Repeat treatment | J11: Medicine Log
A12: 46127 | B12: C004 | C12: Cattle | D12: TREATMENT | E12: East Coast Fever | F12: 40 | G12: Bupalex | H12: 20 ml | I12: Repeat treatment | J12: Medicine Log
A13: 46127 | B13: C105 | C13: Cattle | D13: TREATMENT | E13: East Coast Fever | F13: 40 | G13: Bupalex | H13: 20 ml | I13: Repeat treatment | J13: Medicine Log
A14: 46131 | B14: C111 | C14: Cattle | D14: ILLNESS | E14: East Coast Fever | F14: 40 | G14: Bupalex | H14: 20 ml | J14: Medicine Log
A15: 46133 | B15: C072 | C15: Cattle | D15: ILLNESS | E15: East Coast Fever | F15: 38.6 | G15: Bupalex + Oxytetracycline 10% LA | H15: 20 ml + 15 ml | I15: Card says 'repeated'; the first treatment isn't on the cards | J15: Medicine Log
A16: 46134 | B16: C004 | C16: Cattle | D16: TREATMENT | E16: East Coast Fever | F16: 41 | G16: Bupalex + Oxytetracycline 10% LA | H16: 10 ml + 15 ml | I16: Repeat treatment | J16: Medicine Log
A17: 46136 | B17: C002 | C17: Cattle | D17: ILLNESS | E17: High fever (cause not stated) | F17: 41 | G17: Oxytetracycline 10% LA | H17: 15 ml | J17: Medicine Log
A18: 46140 | B18: C072 | C18: Cattle | D18: TREATMENT | E18: East Coast Fever | F18: 40 | G18: Oxytetracycline 10% LA | H18: 20 ml | I18: Repeat treatment | J18: Medicine Log
A19: 46146 | B19: C025 | C19: Cattle | D19: ILLNESS | E19: East Coast Fever | F19: 41 | G19: Oxytetracycline 10% LA | H19: 20 ml | J19: Medicine Log
A20: 46147 | B20: C072 | C20: Cattle | D20: TREATMENT | E20: East Coast Fever | F20: 41 | G20: Oxytetracycline 10% LA | H20: 15 ml | I20: Repeat treatment | J20: Medicine Log
A21: 46147 | B21: C025 | C21: Cattle | D21: TREATMENT | E21: East Coast Fever | F21: 40 | G21: Oxytetracycline 10% LA | H21: 15 ml | I21: Repeat treatment | J21: Medicine Log
A22: 46148 | B22: C025 | C22: Cattle | D22: TREATMENT | E22: East Coast Fever | F22: 39 | G22: Oxytetracycline 10% LA | H22: 15 ml | I22: Repeat treatment | J22: Medicine Log
A23: 46150 | B23: C072 | C23: Cattle | D23: TREATMENT | E23: East Coast Fever | G23: Oxytetracycline 10% LA | H23: 15 ml | I23: Repeat treatment | J23: Medicine Log
A24: 46150 | B24: S140 | C24: Sheep | D24: ILLNESS | E24: Sick (not stated) | G24: Oxytetracycline 10% LA | H24: 5 ml | J24: Medicine Log
A25: 46153 | B25: C012 | C25: Cattle | D25: ILLNESS | E25: East Coast Fever | F25: 40 | G25: Oxytetracycline 10% LA | H25: 15 ml | J25: Medicine Log
A26: 46158 | B26: G278 | C26: Goat | D26: ILLNESS | E26: Orf | G26: Washed with Magadi salt | H26: 0.5 kg shared by 25 goats | I26: One of 25 goats with Orf | J26: Medicine Log
A27: 46158 | B27: G275 | C27: Goat | D27: ILLNESS | E27: Orf | G27: Washed with Magadi salt | H27: 0.5 kg shared by 25 goats | I27: One of 25 goats with Orf | J27: Medicine Log
A28: 46158 | B28: G209 | C28: Goat | D28: ILLNESS | E28: Orf | G28: Washed with Magadi salt | H28: 0.5 kg shared by 25 goats | I28: One of 25 goats with Orf | J28: Medicine Log
A29: 46158 | B29: G229 | C29: Goat | D29: ILLNESS | E29: Orf | G29: Washed with Magadi salt | H29: 0.5 kg shared by 25 goats | I29: One of 25 goats with Orf | J29: Medicine Log
A30: 46158 | B30: G256 | C30: Goat | D30: ILLNESS | E30: Orf | G30: Washed with Magadi salt | H30: 0.5 kg shared by 25 goats | I30: One of 25 goats with Orf | J30: Medicine Log
A31: 46158 | B31: G251 | C31: Goat | D31: ILLNESS | E31: Orf | G31: Washed with Magadi salt | H31: 0.5 kg shared by 25 goats | I31: One of 25 goats with Orf | J31: Medicine Log
A32: 46158 | B32: G243 | C32: Goat | D32: ILLNESS | E32: Orf | G32: Washed with Magadi salt | H32: 0.5 kg shared by 25 goats | I32: One of 25 goats with Orf | J32: Medicine Log
A33: 46158 | B33: G309 | C33: Goat | D33: ILLNESS | E33: Orf | G33: Washed with Magadi salt | H33: 0.5 kg shared by 25 goats | I33: One of 25 goats with Orf | J33: Medicine Log
A34: 46158 | B34: G289 | C34: Goat | D34: ILLNESS | E34: Orf | G34: Washed with Magadi salt | H34: 0.5 kg shared by 25 goats | I34: One of 25 goats with Orf | J34: Medicine Log
A35: 46158 | B35: G302 | C35: Goat | D35: ILLNESS | E35: Orf | G35: Washed with Magadi salt | H35: 0.5 kg shared by 25 goats | I35: One of 25 goats with Orf | J35: Medicine Log
A36: 46158 | B36: G240 | C36: Goat | D36: ILLNESS | E36: Orf | G36: Washed with Magadi salt | H36: 0.5 kg shared by 25 goats | I36: One of 25 goats with Orf | J36: Medicine Log
A37: 46158 | B37: G298 | C37: Goat | D37: ILLNESS | E37: Orf | G37: Washed with Magadi salt | H37: 0.5 kg shared by 25 goats | I37: One of 25 goats with Orf | J37: Medicine Log
... A79: 46161 | B79: G234 | C79: Goat | D79: TREATMENT | E79: Vulva infection | G79: Methoxicash | H79: 25 ml | I79: Repeat treatment | J79: Medicine Log
A80: 46165 | B80: S252 | C80: Sheep | D80: ILLNESS | E80: Paralysed legs | G80: Oxytetracycline 10% LA | H80: 2 ml | J80: Medicine Log
A81: 46177 | B81: S271 | C81: Sheep | D81: ILLNESS | E81: Lung problem | G81: Oxytetracycline 10% LA | H81: 5 ml | J81: Medicine Log
...

Sheet Group treatments
A1: Date | B1: Species | C1: Activity | D1: Product | E1: Amount | F1: Animals | G1: Notes | H1: Source
A2: 46098 | B2: Cattle | C2: Group treatment (vet) | D2: Ivermectin injection | E2: 690 ml | F2: Whole herd | G2: Bulk herd dose by Vet Naftali | H2: Medicine Log, Ivermectin card
A3: 46098 | B3: Cattle | C3: Group treatment (vet) | D3: Oxytetracycline 10% LA | E3: 1,900 ml | F3: Whole herd | G3: Herd treatment by Vet Naftali | H3: Medicine Log, Oxytetracycline card
A4: 46156 | B4: Not stated | C4: Group treatment | D4: Oxytetracycline 10% LA | E4: 10 ml | F4: Not stated | G4: 'Antiprotozoan control' | H4: Medicine Log, Oxytetracycline card
A5: 46205 | B5: Goat | C5: Group treatment | D5: S-Dime liquid | E5: 5 ml | F5: Goat kids | G5: Given to goat kids | H5: Medicine Log, S-Dime Liquid card
A6: 46215 | B6: Goat | C6: Tick spraying | D6: Spray (product not written) | E6: 100 ml | F6: Herd | H6: Daily Activity Tracker
A7: 46219 | B7: Goat | C7: Deworming | D7: Nilzan | E7: 287 ml | F7: 26 goats + 27 kids | G7: 10 ml per goat, 1 ml per kid | H7: Daily Activity Tracker
A8: 46219 | B8: Goat | C8: Group treatment | D8: Tetracycline | E8: 78 ml | F8: 26 goats | G8: 3 ml per goat | H8: Daily Activity Tracker
A9: 46219 | B9: Sheep, goats, calves | C9: Supplement | D9: Magnesium lick salt | E9: 7 kg | F9: Herd | H9: Daily Activity Tracker
A10: 46221 | B10: Cattle | C10: Tick spraying | D10: Spray (product not written) | E10: 300 ml | F10: Herd | H10: Daily Activity Tracker
A11: 46222 | B11: Goat | C11: Dipping | D11: Not written | E11: Not written | F11: Herd | G11: Goats and sheep dipped | H11: Daily Activity Tracker (20/7 note)
A12: 46222 | B12: Sheep | C12: Dipping | D12: Not written | E12: Not written | F12: Flock | G12: Goats and sheep dipped | H12: Daily Activity Tracker (20/7 note)
A13: 46225 | B13: Cattle | C13: Dipping | D13: Dominex | E13: 300 ml | F13: Herd | H13: Daily Activity Tracker
A14: 46228 | B14: Cattle | C14: Dipping | D14: Not written | E14: 300 ml | F14: Herd | H14: Daily Activity Tracker
A15: 46235 | B15: Cattle | C15: Dipping | D15: Not written | E15: 300 ml | F15: Herd | H15: Daily Activity Tracker
A16: 46235 | B16: Goat | C16: Dipping | D16: Not written | E16: 100 ml | F16: Herd | H16: Daily Activity Tracker
A17: 46239 | B17: Cattle | C17: Dipping | D17: Dominex | E17: 300 ml | F17: Herd | H17: Daily Activity Tracker
A18: 46241 | B18: Goat | C18: Tick spraying | D18: Spray (product not written) | E18: 100 ml | F18: Herd | H18: Daily Activity Tracker
A19: 46247 | B19: Goat | C19: Dipping | D19: Not written | E19: 100 ml | F19: Herd | H19: Daily Activity Tracker
A20: 46252 | B20: Sheep | C20: Deworming | D20: Albendex 25 | E20: 1,500 ml | F20: All sheep | H20: Daily Activity Tracker
A21: 46254 | B21: Goat | C21: Deworming | D21: Albendex 25 | E21: 500 ml | F21: 92 goats | H21: Daily Activity Tracker
A22: 46255 | B22: Cattle | C22: Tick spraying | D22: Dominex | E22: 150 ml | F22: Herd | H22: Daily Activity Tracker, Inputs Applied
A23: 46260 | B23: Cattle | C23: Tick spraying | D23: Dominex | E23: 200 ml | F23: Herd | H23: Daily Activity Tracker
A24: 46263 | B24: Sheep | C24: Deworming (injection) | D24: Ivermectin | E24: 100 ml | F24: 100 sheep | G24: Internal and external parasites | H24: Daily Activity Tracker
A25: 46266 | B25: Sheep | C25: Group treatment | D25: Oxytetracycline + Multi-Vit | E25: 423 ml + 400 ml | F25: Whole flock | H25: Daily Activity Tracker
A27: The Dominex card also shows about 90 sprays from May to August 2026 (cattle about 300 ml, goats and sheep about 100 ml, every 2-3 days), but they weren't typed out one by one, so only the dated ones are listed here.

Sheet Weights
A1: Date | B1: Tag | C1: Species | D1: Weight (kg) | E1: Note | F1: Source
A2: 45838 | B2: C331 | C2: Cattle | D2: 360 | E2: Weight at sale | F2: 2025 Cow Sales Weight sheet
A3: 45838 | B3: C208 | C3: Cattle | D3: 392 | E3: Weight at sale | F3: 2025 Cow Sales Weight sheet
A4: 45838 | B4: C233 | C4: Cattle | D4: 360 | E4: Weight at sale | F4: 2025 Cow Sales Weight sheet
A5: 45838 | B5: C222 | C5: Cattle | D5: 459 | E5: Weight at sale | F5: 2025 Cow Sales Weight sheet
A6: 45838 | B6: C207 | C6: Cattle | D6: 372 | E6: Weight at sale | F6: 2025 Cow Sales Weight sheet
A7: 45838 | B7: C218 | C7: Cattle | D7: 427 | E7: Weight at sale | F7: 2025 Cow Sales Weight sheet
A8: 45838 | B8: C216 | C8: Cattle | D8: 420 | E8: Weight at sale | F8: 2025 Cow Sales Weight sheet
A9: 45838 | B9: C202 | C9: Cattle | D9: 420 | E9: Weight at sale | F9: 2025 Cow Sales Weight sheet
A10: 45838 | B10: C209 | C10: Cattle | D10: 384 | E10: Weight at sale | F10: 2025 Cow Sales Weight sheet
A11: 45838 | B11: C212 | C11: Cattle | D11: 451 | E11: Weight at sale | F11: 2025 Cow Sales Weight sheet
A12: 45881 | B12: C229 | C12: Cattle | D12: 300 | E12: Weight at sale | F12: 2025 Cow Sales Weight sheet rows 11-12 (KES 310/kg live)
A13: 45881 | B13: C230 | C13: Cattle | D13: 270 | E13: Weight at sale | F13: 2025 Cow Sales Weight sheet rows 11-12 (KES 310/kg live)
... A21: 46252 | B21: G208 | C21: Goat | D21: 25.4 | E21: Weight at sale | F21: Daily Activity Tracker, Sales: 7 he-goats, 178 kg, KES 62,300 (shared equally)

Sheet Pharmacy
A1: Medicine | B1: Opening stock | C1: Latest balance | D1: Dates on the card | E1: Note from the digitised log
A2: Medicine | B2: Opening Stock | C2: Latest Balance | D2: Date Range | E2: Status
A3: Bupalex (Buparvaquone) - ECF | B3: 200 mls | C3: 40 mls (as of 29/6/2026); NIL per 13/8/2026 count - unreconciled | D3: 25/3/2026 - 13/8/2026 | E3: Unchanged this update
A4: Ivermectin Injection | B4: 700 mls | C4: 0 mls | D4: 17/3/2026 - 13/8/2026 | E4: Unchanged this update
A5: Oxytetracycline 10% LA | B5: 3,000 mls | C5: 844 mls (4/6/2026); likely continues to ~630-650mls by Sept - see sheet note | D5: 17/3/2026 - 4/6/2026 (+ unconfirmed continuation) | E5: Continuation page found but not re-sequenced - verify
A6: Nilzan | B6: 1,700 mls | C6: 1,700 mls | D6: 13/8/2026 (single stock count) | E6: Unchanged - no new data found
A7: Penstrep | B7: ~90 mls (approx) | C7: ~55 mls (approx) | D7: Card dates not individually transcribed | E7: Partially updated - opening/closing only, verify
A8: Dexa (Dexamethasone Injection 0.2g) | B8: 2,400 mls received / 200 mls opening | C8: 119 mls | D8: 17/3/2026 - 27/8/2026 | E8: Fully updated with new card
A9: Magadi Salt | B9: ~14.5 kg (approx) | C9: Nil (as of 18/5/2026) | D9: 14/5/2026 - 6/7/2026 | E9: New sheet - confirmed distinct product from Mack Lick Salt
A10: Mack Lick Salt | B10: 0 | C10: 0 | D10: 13/8/2026 (single stock count) | E10: Restored 2026-08-30 - separate product from Magadi Salt, was briefly (incorrectly) merged
A11: Nutri-Vit | B11: 0 | C11: 0 | D11: 13/8/2026 (single stock count) | E11: Unchanged - no new data found
A12: Alamycin 30% (name uncertain) | B12: 26 mls | C12: 26 mls | D12: 13/8/2026 (single stock count) | E12: Unchanged - no new data found
... A21: Dewormer (product name unclear) | B21: n/a | C21: n/a | D21: Undated | E21: New sheet - narrative-only, no dates/quantities legible
A23: Every line on the medicine cards
A24: Medicine card | B24: Date | C24: Received | D24: Used | E24: Balance | F24: Treatment / notes | G24: Check
A25: Bupalex (ECF) | B25: Opening stock | C25: 4 x 50mls (200mls) | E25: 200.0 | F25: Opening balance
A26: Bupalex (ECF) | B26: 25/3/2026 | D26: 10.0 | E26: 190.0 | F26: Treated sick calve no. 116
A27: Bupalex (ECF) | B27: 11/4/2026 | D27: 20.0 | E27: 170.0 | F27: Treated calve no. 105, ECF, temp 40
A28: Bupalex (ECF) | B28: 12/04/2026 | D28: 20.0 | E28: 150.0 | F28: Repeated same sick calve no. 105
A29: Bupalex (ECF) | B29: 12/04/2026 | D29: 20.0 | E29: 130.0 | F29: New case: treated she-cow no. 004 with ECF, temp 40
A30: Bupalex (ECF) | B30: 12/04/2026 | D30: 20.0 | E30: 110.0 | F30: Treated he-cow, new case, ECF, temp 40, no. 108
A31: Bupalex (ECF) | B31: 15/4/2026 | D31: 10.0 | E31: 100.0 | F31: Repeated sick cow no. 108
A32: Bupalex (ECF) | B32: 15/4/2026 | D32: 20.0 | E32: 80.0 | F32: Repeated sick cow no. 004, temp 40
A33: Bupalex (ECF) | B33: 15/4/2026 | D33: 20.0 | E33: 60.0 | F33: Repeated sick cow no. 105, temp 40
A34: Bupalex (ECF) | B34: 16/4/2026 | E34: 65.0 | F34: Balance reverification | G34: Arithmetic break in original - verify against notebook
A35: Bupalex (ECF) | B35: 18/4/2026 | D35: 20.0 | E35: 45.0
A36: Bupalex (ECF) | B36: 19/4/2026 | D36: 20.0 | E36: 30.0 | F36: Treated cow no. 111 with ECF, temp 40 | G36: Balance doesn't reconcile exactly to prior row (45-20=25, not 30) - verify
A37: Bupalex (ECF) | B37: 21/4/2026 | D37: 20.0 | E37: 10.0 | F37: Repeated cow no. 72, ECF, temp 38.6
A38: Bupalex (ECF) | B38: 22/4/2026 | D38: 10.0 | F38: Repeated cow no. 004, temp 41, ECF
A39: Bupalex (ECF) | B39: 29/6/2026 | C39: 50 (from safe) | E39: 50.0 | F39: NB: 50mls sourced "from safe" (new stock, not a formal delivery)
A40: Bupalex (ECF) | B40: 29/6/2026 | D40: 10.0 | E40: 40.0 | F40: Treated sick calf, temp 41, ECF (signed Julie, 3/7)
A41: Bupalex (ECF) | B41: 13/8/2026 | F41: Physical stock count (13/8/2026 balances sheet): recorded as NIL. Prior running balance was 40mls (29/6/2026) - no Used entries are logged between 29/6 and 13/8 to account for the drop, so either usage wasn't logged in this gap or this reading is a different product (scan reads 'Buparcin'/'Buparvon' - spelling varies across scans, treated as the same drug as Bupalex/Buparvet elsewhere). The same day's requirements list separately notes 50ml of this product as needed - not logged as Received since it's a request, not a confirmed delivery. | G41: Balance drop from 40 to NIL is unexplained by logged usage - verify against physical stock and 29/6-13/8 treatment records
A42: Ivermectin Injection | B42: Opening stock | C42: 7 x 100mls (700mls) | E42: 700.0 | F42: Opening balance
A43: Ivermectin Injection | B43: 17/3/2026 | D43: 690.0 | E43: 10.0 | F43: bulk herd dose
A44: Ivermectin Injection | B44: 25/3/2026 | D44: 10.0 | F44: Treated free-roaming/new bull
A45: Ivermectin Injection | B45: 13/8/2026 | F45: Physical stock count (13/8/2026 balances sheet, read as 'Evermectin'): recorded as NIL, consistent with the running balance of 0 already on record since 25/3/2026.
A46: Oxytetracycline 10% LA | B46: Opening stock | C46: 6 x 500mls (3,000mls) | E46: 3000.0 | F46: Opening balance. Separate note in margin: "Lot issued 500mls"
A47: Oxytetracycline 10% LA | B47: 17/3/2026 | D47: 1900.0 | E47: 1100.0 | F47: Herd treatment
A48: Oxytetracycline 10% LA | B48: 25/3/2026 | D48: 20.0 | E48: 1080.0 | F48: Treated the new bull
A49: Oxytetracycline 10% LA | B49: 25/3/2026 | D49: 10.0 | E49: 1070.0 | F49: Repeated: free sick calve no. 116
...

Sheet Head-count check
A1: Month end (or last record) | B1: Species | C1: Tracker count (real) | D1: Animals tab count | E1: Difference
A2: 45688 | B2: Cattle | C2: 138 | D2: =COUNTIFS(Animals!$B:$B,B2,Animals!$H:$H,"<="&A2,Animals!$K:$K,">"&A2)+COUNTIFS(Animals!$B:$B,B2,Animals!$H:$H,"<="&A2,Animals!$K:$K,"") -> 138 | E2: =D2-C2 -> 0
A3: 45716 | B3: Cattle | C3: 137 | D3: =COUNTIFS(Animals!$B:$B,B3,Animals!$H:$H,"<="&A3,Animals!$K:$K,">"&A3)+COUNTIFS(Animals!$B:$B,B3,Animals!$H:$H,"<="&A3,Animals!$K:$K,"") -> 137 | E3: =D3-C3 -> 0
A4: 45747 | B4: Cattle | C4: 137 | D4: =COUNTIFS(Animals!$B:$B,B4,Animals!$H:$H,"<="&A4,Animals!$K:$K,">"&A4)+COUNTIFS(Animals!$B:$B,B4,Animals!$H:$H,"<="&A4,Animals!$K:$K,"") -> 137 | E4: =D4-C4 -> 0
A5: 45777 | B5: Cattle | C5: 138 | D5: =COUNTIFS(Animals!$B:$B,B5,Animals!$H:$H,"<="&A5,Animals!$K:$K,">"&A5)+COUNTIFS(Animals!$B:$B,B5,Animals!$H:$H,"<="&A5,Animals!$K:$K,"") -> 138 | E5: =D5-C5 -> 0
A6: 45808 | B6: Cattle | C6: 137 | D6: =COUNTIFS(Animals!$B:$B,B6,Animals!$H:$H,"<="&A6,Animals!$K:$K,">"&A6)+COUNTIFS(Animals!$B:$B,B6,Animals!$H:$H,"<="&A6,Animals!$K:$K,"") -> 137 | E6: =D6-C6 -> 0
A7: 45838 | B7: Cattle | C7: 127 | D7: =COUNTIFS(Animals!$B:$B,B7,Animals!$H:$H,"<="&A7,Animals!$K:$K,">"&A7)+COUNTIFS(Animals!$B:$B,B7,Animals!$H:$H,"<="&A7,Animals!$K:$K,"") -> 127 | E7: =D7-C7 -> 0
A8: 45869 | B8: Cattle | C8: 127 | D8: =COUNTIFS(Animals!$B:$B,B8,Animals!$H:$H,"<="&A8,Animals!$K:$K,">"&A8)+COUNTIFS(Animals!$B:$B,B8,Animals!$H:$H,"<="&A8,Animals!$K:$K,"") -> 127 | E8: =D8-C8 -> 0
A9: 45900 | B9: Cattle | C9: 123 | D9: =COUNTIFS(Animals!$B:$B,B9,Animals!$H:$H,"<="&A9,Animals!$K:$K,">"&A9)+COUNTIFS(Animals!$B:$B,B9,Animals!$H:$H,"<="&A9,Animals!$K:$K,"") -> 123 | E9: =D9-C9 -> 0
A10: 45930 | B10: Cattle | C10: 122 | D10: =COUNTIFS(Animals!$B:$B,B10,Animals!$H:$H,"<="&A10,Animals!$K:$K,">"&A10)+COUNTIFS(Animals!$B:$B,B10,Animals!$H:$H,"<="&A10,Animals!$K:$K,"") -> 122 | E10: =D10-C10 -> 0
A11: 45961 | B11: Cattle | C11: 104 | D11: =COUNTIFS(Animals!$B:$B,B11,Animals!$H:$H,"<="&A11,Animals!$K:$K,">"&A11)+COUNTIFS(Animals!$B:$B,B11,Animals!$H:$H,"<="&A11,Animals!$K:$K,"") -> 104 | E11: =D11-C11 -> 0
A12: 45991 | B12: Cattle | C12: 108 | D12: =COUNTIFS(Animals!$B:$B,B12,Animals!$H:$H,"<="&A12,Animals!$K:$K,">"&A12)+COUNTIFS(Animals!$B:$B,B12,Animals!$H:$H,"<="&A12,Animals!$K:$K,"") -> 108 | E12: =D12-C12 -> 0
A13: 46022 | B13: Cattle | C13: 112 | D13: =COUNTIFS(Animals!$B:$B,B13,Animals!$H:$H,"<="&A13,Animals!$K:$K,">"&A13)+COUNTIFS(Animals!$B:$B,B13,Animals!$H:$H,"<="&A13,Animals!$K:$K,"") -> 112 | E13: =D13-C13 -> 0
... A56: 46283 | B56: Sheep | C56: 143 | D56: =COUNTIFS(Animals!$B:$B,B56,Animals!$H:$H,"<="&A56,Animals!$K:$K,">"&A56)+COUNTIFS(Animals!$B:$B,B56,Animals!$H:$H,"<="&A56,Animals!$K:$K,"") -> 143 | E56: =D56-C56 -> 0
A58: The 'Animals tab count' counts animals that had joined and not yet left on that date. A difference of 0 means the rebuilt animals add up to the farm's real count.

Sheet Notebook 2020-21
A1: Photo | B1: Book | C1: Dates on the page | D1: First row (as read) | E1: Last row (as read) | F1: Remarks read
A2: Data3.jpeg | B2: Cows and calves | C2: 17/3/2020 - 26/3/2020 | D2: He 14, She 62, calves He 19, She 24: total 119 | E2: He 14, She 62, calves He 20, She 23: total 119 | F2: '1 He calve new born'; '1 She calve died'
A3: Data2.jpeg | B3: Goats and sheep | C3: 4/4/2020 - 14/4/2020 | D3: Goats He 27, She 54, kids He 6, She 3: total 90; sheep about 157; all small stock 243 - 245 | E3: Goats total 90; sheep about 165; all small stock about 247 | F3: Several sheep births and one sheep death noted in red (partly unreadable)
A4: Data4.jpeg | B4: Cows and calves | C4: 11/5/2020 - 21/5/2020 | D4: He 14, She 62, calves He 18, She 25: total 119 | E4: He 14, She 62, calves He 18, She 26: total 120 | F4: One calf added about 13/5 (no remark readable)
A5: Data1.jpeg | B5: Goats and sheep | C5: 18/5/2020 - 28/5/2020 | D5: Goats He 25, She 51, kids He 3, She 2: total 81; sheep about 161; small stock 239 | E5: Goats about 78; sheep about 155; small stock about 227 | F5: Sheep sold and died (red remarks, partly unreadable)
A6: WhatsApp_Image_2026-11-01_at_19.45.13.jpeg | B6: Goats and sheep | C6: 9/6/2020 - 19/6/2020 | D6: Goats He 25, She 48, kids He 3, She 1: total 77; sheep about 152; small stock 221 | E6: Goats about 77; sheep about 149; small stock about 220 | F6: Remarks in red about sheep (partly unreadable)
A7: Data5.jpeg | B7: Cows and calves | C7: 13/6/2020 - 23/6/2020 | D7: He 13, She 61, calves He 18, She 26: total 118 | E7: He 13, She 60, calves He 20, She 27: total 120 | F7: 'One she cow died' (16/6); '2 He calves new born, 1 She calve new born' (19/6)
A8: Data6.jpeg | B8: Cows and calves | C8: 9/9/2020 - 19/9/2020 | D8: He 14, She 66, calves He 12, She 18: total 110 | E8: He 15, She 66, calves He 12, She 17: total 110 | F8: '1 Bull bought' (14/9); '1 She calve died' (17/9)
A9: Data7.jpeg | B9: Cows and calves | C9: 13/11/2020 - 23/11/2020 | D9: He 15, She 66, calves He 13, She 17: total 111 | E9: He 15, She 66, calves He 15, She 21: total 117 | F9: '1 He calf new born' (14/11); '1 She calve new born' (19/11); '1 She calve new born' (22/11); '1 He calve new born' (23/11)
A10: Data9.jpeg | B10: Goats and sheep | C10: 16/5/2021 - 26/5/2021 | D10: Goats He 29, She 54, kids He 3, She 4: total 90; sheep He 41, She 117; lambs He 10, She 13; small stock 181 | E10: Goats He 31, She 54: total 90; sheep about 114; small stock 177 | F10: '2 She sheep sold'; '1 She sheep died'; '1 He sheep died' (dates partly unreadable)
A11: Data8.jpeg | B11: Goats and sheep | C11: 18/6/2021 - 28/6/2021 | D11: Goats He 31, She 54, kids He 4, She 6: total 95; sheep about 114; small stock 180 | E11: Goats about 93; sheep about 117; small stock about 181 | F11: '2 She sheep sold'; '1 She sheep sold'; '2 He new born'; '1 He sheep sold, 1 She sheep sold'; '1 She goat died'
A13: These pages are from 2020 and 2021. The photos were taken sideways or upside down and some figures are faint, so numbers marked 'about' are best readings: please check them against the books. None of these animals are still on the farm, so this tab is history only and isn't used on the Animals tab.

Sheet Problems found
A1: Date | B1: Species | C1: What doesn't add up, and what we did | D1: Source
B2: Goats, sheep | C2: The 2025 - 2026 Goat and Sheep Tracker sheets repeat the COW numbers from 1/1/2025 to 30/5/2025 (copied from the cow sheet). Goats and sheep are therefore rebuilt from 31/5/2025. | D2: Livestock Tracker
A3: 46169 | B3: Sheep | C3: The note says '1 She sheep bitten by Hyena (#170)', but the count shows a male adult going down. The count is followed, so S170 is shown as a male. | D3: Livestock Tracker
A4: 46158 | B4: Cattle | C4: The note repeats '1 she cow died on 27th Number 004' (already recorded on 28/4). A second female cow left the count; her cause is shown as not recorded. | D4: Livestock Tracker
A5: 46235 | B5: Cattle / sheep | C5: The Histacine card says it treated a sheep with a lung problem on 1/8; the Activity Tracker says a he-cow with anaplasmosis. The Activity Tracker version is used. | D5: Medicine Log / Activity Tracker
A6: 46239 | B6: All | C6: The Activity Tracker counts animals without tags: cattle 8 male, 43 female; calves 18 male, 12 female; goats 5 male, 8 female, 21 kids; sheep 20 male, 26 female. Most animals were untagged, so few real numbers exist. | D6: Activity Tracker
A7: 46136 | B7: Goat | C7: '1 she goat lost' was never followed by 'found'; shown as Lost. | D7: Livestock Tracker
B8: Medicine | C8: Some medicine cards don't add up row to row (Bupalex 16/4 and 19/4/2026, S-Dime tabs 26/8/2026, Histacine 6/5/2026), and the Penstrep, Bupacin and Dominex cards were only summarised. See the 'Check' column on the Pharmacy tab. | D8: Medicine Log
A9: 46139 | B9: Cattle | C9: Cow 004 died on 27/4 but the book recorded it on 28/4, so the Head-count check can be 1 out for that single day. Month ends are not affected. | D9: Livestock Tracker
A10: 45808 | B10: Cattle | C10: Count moved 2 from female to male with no note; treated as a correction of sex. | D10: Livestock Tracker, 2025 - 2026 Cow Tracker, 31/05/2025
A11: 45808 | B11: Cattle | C11: One male adult was added to the count with no birth or purchase noted; shown as 'Appeared in the count'. | D11: Livestock Tracker, 2025 - 2026 Cow Tracker, 31/05/2025
A12: 45882 | B12: Goat | C12: One male young left the count with no explanation; shown as 'Missing (count correction)'. | D12: Livestock Tracker, 2025 - 2026 Goat Tracker, 13/08/2025
A13: 45891 | B13: Goat | C13: One female young was added to the count with no birth or purchase noted; shown as 'Appeared in the count'. | D13: Livestock Tracker, 2025 - 2026 Goat Tracker, 22/08/2025: "No explanation"
A14: 45891 | B14: Goat | C14: One female young was added to the count with no birth or purchase noted; shown as 'Appeared in the count'. | D14: Livestock Tracker, 2025 - 2026 Goat Tracker, 22/08/2025: "No explanation"
A15: 45900 | B15: Goat | C15: One female young left the count with no explanation; shown as 'Missing (count correction)'. | D15: Livestock Tracker, 2025 - 2026 Goat Tracker, 31/08/2025: "No explanation"
A16: 45905 | B16: Goat | C16: One female adult left the count with no explanation; shown as 'Missing (count correction)'. | D16: Livestock Tracker, 2025 - 2026 Goat Tracker, 05/09/2025: "No explanation"
A17: 45973 | B17: Goat | C17: One female adult left the count with no explanation; shown as 'Missing (count correction)'. | D17: Livestock Tracker, 2025 - 2026 Goat Tracker, 12/11/2025: "Counting correction (overall animals - sheep and goats are 233. With the correct tally for sheep then the goats should be 98"
A18: 45973 | B18: Goat | C18: One female adult left the count with no explanation; shown as 'Missing (count correction)'. | D18: Livestock Tracker, 2025 - 2026 Goat Tracker, 12/11/2025: "Counting correction (overall animals - sheep and goats are 233. With the correct tally for sheep then the goats should be 98"
A19: 46064 | B19: Goat | C19: Count moved 1 from male to female with no note; treated as a correction of sex. | D19: Livestock Tracker, 2025 - 2026 Goat Tracker, 11/02/2026: "After tagging"
A20: 46064 | B20: Sheep | C20: Count moved 4 from male to female with no note; treated as a correction of sex. | D20: Livestock Tracker, 2025-2026 Sheep Tracker, 11/02/2026: "Audit"
... A27: 46261 | B27: Sheep | C27: One female young left the count with no explanation; shown as 'Missing (count correction)'. | D27: Livestock Tracker, 2025-2026 Sheep Tracker, 27/08/2026: "Correction"
